<mujoco>
    <option timestep="0.0002" />
    <actuator>
        <motor gear="0.05" joint="hinge_1" name="actuator_motor" ctrlrange="-300 300" ctrllimited="true"/>
        <motor gear="0.05" joint="hinge_5" name="actuator_motor2" ctrlrange="-300 300" ctrllimited="true"/>
    </actuator>
    <asset>
        <material name="blue" rgba="0 0 1 1" />
        <material name="green" rgba="0 1 0 1" />
        <material name="red" rgba="1 0 0 1" />
        <material name="white" rgba="1 1 1 1" />
    </asset>
    <worldbody>
        <geom type="plane" size="1 1 0.1" pos="0 0 -0.5" rgba=".9 0 0 1" />
        <light diffuse=".5 .5 .5" pos="0 0 10" dir="0 0 -1" />
        <body name="link_1" pos="0 0 0">
            <joint name="hinge_1" pos="0 0 0" axis="1 0 0" />
            <geom type="cylinder" size=".01 0.2" pos="0 0 0.2" euler="0 0 0" material="red" />
            <geom type="cylinder" size=".0198 .0115" pos="0 0 0.4" euler="0 90 0" material="red" mass="0.065"/>
            <geom type="cylinder" size=".0198 .0115" pos="0 0 0" euler="0 90 0" material="red" mass="0.065"/>
            <body name="link_2" pos="0.023 0 0.4" euler="0 0 0">
                <joint name="hinge_2" pos="0 0 0" axis="1 0 0" />
                <geom type="cylinder" size=".01 0.2" pos="0 0.2 0" euler="90 0 0" material="blue" />
                <geom type="cylinder" size=".0198 .0115" pos="0 0.4 0" euler="0 90 0" material="blue" />
                <geom type="cylinder" size=".0198 .0115" pos="0 0 0" euler="0 90 0" material="blue" />
                <body name="link_3" pos="-0.023 0.4 0" euler="-90 0 0">
                    <joint name="hinge_3" pos="0 0 0" axis="1 0 0" />
                    <geom type="cylinder" size=".01 0.2" pos="0 0 0.2" euler="0 0 0" material="green" />
                    <geom type="cylinder" size=".0198 .0115" pos="0 0 0" euler="0 90 0" material="green" />
                    <geom type="cylinder" size=".0198 .0115" pos="0 0 0.4" euler="0 90 0" material="green" />
                    <body name="link_4" pos="0.023 0 0.4" euler="180 0 0">
                        <joint name="hinge_4" pos="0 0 0" axis="1 0 0" />
                        <geom type="cylinder" size=".01 0.2" pos="0 -0.2 0" euler="90 0 0" material="white" />
                        <geom type="cylinder" size=".0198 .0115" pos="0 0 0" euler="0 90 0" material="white" />
                        <body name="link_5" pos="0 -0.4 0" euler="0 0 0">
                            <joint name="hinge_5" pos="0 0 0" axis="1 0 0" />
                                <geom type="cylinder" size=".0198 .0115" pos="0 0 0" euler="0 90 0" material="white" />
                        </body>
                    </body>
                </body>
            </body>
        </body>
    </worldbody>
    <equality>
        <connect name="kinematic_link" active="true" body1="link_5" anchor="0 0 0" />
    </equality>
<!--    <contact>-->
<!--        <exclude body1="link_1" body2="link_2"/>-->
<!--        <exclude body1="link_1" body2="link_3"/>-->
<!--        <exclude body1="link_1" body2="link_4"/>-->
<!--        <exclude body1="link_2" body2="link_3"/>-->
<!--        <exclude body1="link_2" body2="link_4"/>-->
<!--        <exclude body1="link_3" body2="link_4"/>-->
<!--    </contact>-->
</mujoco>