<?xml version="1.0" ?>
<robot name="parallel_manipulator">

<mujoco>
 <compiler balanceinertia="true" discardvisual="false" meshdir="meshes" fusestatic="false"/>
</mujoco>

<material name="silver">
  <color rgba="0.700 0.700 0.700 1.000"/>
</material>

<link name="base_link">
  <inertial>
    <origin xyz="5.026061718855929e-18 0.0 -0.16000000000000003" rpy="0 0 0"/>
    <mass value="0.0554883802440297"/>
    <inertia ixx="3.583624557426321e-06" iyy="3.583624557426321e-06" izz="6.242442777453249e-06" ixy="0.0" iyz="2.091660178393795e-21" ixz="6.972200594645924e-22"/>
  </inertial>
  <visual>
    <origin xyz="0 0 0" rpy="0 0 0"/>
    <geometry>
      <mesh filename="meshes/base_link.stl" scale="0.001 0.001 0.001"/>
    </geometry>
    <material name="silver"/>
  </visual>
  <collision>
    <origin xyz="0 0 0" rpy="0 0 0"/>
    <geometry>
      <mesh filename="meshes/base_link.stl" scale="0.001 0.001 0.001"/>
    </geometry>
  </collision>
</link>

<link name="base11">
  <inertial>
    <origin xyz="0.07770643358085871 3.0322658174603484e-07 0.06024385622848319" rpy="0 0 0"/>
    <mass value="0.08674351614300567"/>
    <inertia ixx="0.00021167094510036208" iyy="0.0003141097173175293" izz="0.00010389479527303026" ixy="-9.152163667196695e-10" iyz="-2.4938792392235243e-09" ixz="-0.0001301534291036009"/>
  </inertial>
  <visual>
    <origin xyz="-0.0 -0.0 0.155" rpy="0 0 0"/>
    <geometry>
      <mesh filename="meshes/base11.stl" scale="0.001 0.001 0.001"/>
    </geometry>
    <material name="silver"/>
  </visual>
  <collision>
    <origin xyz="-0.0 -0.0 0.155" rpy="0 0 0"/>
    <geometry>
      <mesh filename="meshes/base11.stl" scale="0.001 0.001 0.001"/>
    </geometry>
  </collision>
</link>

<link name="base21">
  <inertial>
    <origin xyz="-0.03863393418963683 0.06691531907153667 0.05790924389468903" rpy="0 0 0"/>
    <mass value="0.08514522253227381"/>
    <inertia ixx="0.00026993000986479153" iyy="0.0002192885840932424" izz="0.00010271544678743677" ixy="4.385861472446938e-05" iyz="-0.00010739274184498333" ixz="6.200602713378632e-05"/>
  </inertial>
  <visual>
    <origin xyz="-0.0 -0.0 0.15" rpy="0 0 0"/>
    <geometry>
      <mesh filename="meshes/base21.stl" scale="0.001 0.001 0.001"/>
    </geometry>
    <material name="silver"/>
  </visual>
  <collision>
    <origin xyz="-0.0 -0.0 0.15" rpy="0 0 0"/>
    <geometry>
      <mesh filename="meshes/base21.stl" scale="0.001 0.001 0.001"/>
    </geometry>
  </collision>
</link>

<link name="base31">
  <inertial>
    <origin xyz="-0.03841038126169106 -0.06652936154357646 0.05558210977220143" rpy="0 0 0"/>
    <mass value="0.08354709335152774"/>
    <inertia ixx="0.0002523299000617631" iyy="0.00020227077725309148" izz="0.00010151774390270406" ixy="-4.335059504519329e-05" iyz="0.00010214693498486162" ixz="5.897184287090014e-05"/>
  </inertial>
  <visual>
    <origin xyz="-0.0 -0.0 0.145" rpy="0 0 0"/>
    <geometry>
      <mesh filename="meshes/base31.stl" scale="0.001 0.001 0.001"/>
    </geometry>
    <material name="silver"/>
  </visual>
  <collision>
    <origin xyz="-0.0 -0.0 0.145" rpy="0 0 0"/>
    <geometry>
      <mesh filename="meshes/base31.stl" scale="0.001 0.001 0.001"/>
    </geometry>
  </collision>
</link>

<link name="base_top1">
  <inertial>
    <origin xyz="-0.04131878844100827 0.0689319282604722 -4.945697337739286e-05" rpy="0 0 0"/>
    <mass value="0.06760520920400498"/>
    <inertia ixx="8.072621684546594e-05" iyy="8.115338367189903e-05" izz="0.00016072792841683608" ixy="7.233128143425066e-05" iyz="-2.129572243479971e-09" ixz="1.1992591402244904e-09"/>
  </inertial>
  <visual>
    <origin xyz="-0.11 4.2e-05 -4.9e-05" rpy="0 0 0"/>
    <geometry>
      <mesh filename="meshes/base_top1.stl" scale="0.001 0.001 0.001"/>
    </geometry>
    <material name="silver"/>
  </visual>
  <collision>
    <origin xyz="-0.11 4.2e-05 -4.9e-05" rpy="0 0 0"/>
    <geometry>
      <mesh filename="meshes/base_top1.stl" scale="0.001 0.001 0.001"/>
    </geometry>
  </collision>
</link>

<link name="base_top21">
  <inertial>
    <origin xyz="-0.03903703371795239 -0.0702492901574557 -4.945697337739699e-05" rpy="0 0 0"/>
    <mass value="0.06760520920400423"/>
    <inertia ixx="0.0001436873191756333" iyy="1.819228134173007e-05" izz="0.00016072792841683467" ixy="-3.598067205545254e-05" iyz="2.10337500289663e-09" ixz="1.2446340919535983e-09"/>
  </inertial>
  <visual>
    <origin xyz="0.054964 -0.095284 -4.9e-05" rpy="0 0 0"/>
    <geometry>
      <mesh filename="meshes/base_top21.stl" scale="0.001 0.001 0.001"/>
    </geometry>
    <material name="silver"/>
  </visual>
  <collision>
    <origin xyz="0.054964 -0.095284 -4.9e-05" rpy="0 0 0"/>
    <geometry>
      <mesh filename="meshes/base_top21.stl" scale="0.001 0.001 0.001"/>
    </geometry>
  </collision>
</link>

<link name="base_top31">
  <inertial>
    <origin xyz="0.08035582215896059 0.001317361896983657 -4.9456973377392864e-05" rpy="0 0 0"/>
    <mass value="0.0676052092040043"/>
    <inertia ixx="1.8405864754947538e-05" iyy="0.00014347373576241605" izz="0.0001607279284168349" ixy="-3.63506093787976e-05" iyz="2.6197240595179076e-11" ixz="-2.443893232161633e-09"/>
  </inertial>
  <visual>
    <origin xyz="0.055036 0.095242 -4.9e-05" rpy="0 0 0"/>
    <geometry>
      <mesh filename="meshes/base_top31.stl" scale="0.001 0.001 0.001"/>
    </geometry>
    <material name="silver"/>
  </visual>
  <collision>
    <origin xyz="0.055036 0.095242 -4.9e-05" rpy="0 0 0"/>
    <geometry>
      <mesh filename="meshes/base_top31.stl" scale="0.001 0.001 0.001"/>
    </geometry>
  </collision>
</link>

<joint name="Rigid_26" type="fixed">
  <origin xyz="0.0 0.0 -0.155" rpy="0 0 0"/>
  <parent link="base_link"/>
  <child link="base11"/>
</joint>

<joint name="Revolute_27" type="continuous">
  <origin xyz="0.0 0.0 0.005" rpy="0 0 0"/>
  <parent link="base11"/>
  <child link="base21"/>
  <axis xyz="0.0 0.0 -1.0"/>
</joint>
<transmission name="Revolute_27_tran">
  <type>transmission_interface/SimpleTransmission</type>
  <joint name="Revolute_27">
    <hardwareInterface>PositionJointInterface</hardwareInterface>
  </joint>
  <actuator name="Revolute_27_actr">
    <hardwareInterface>PositionJointInterface</hardwareInterface>
    <mechanicalReduction>1</mechanicalReduction>
  </actuator>
</transmission>

<joint name="Revolute_28" type="continuous">
  <origin xyz="0.0 0.0 0.005" rpy="0 0 0"/>
  <parent link="base21"/>
  <child link="base31"/>
  <axis xyz="0.0 0.0 -1.0"/>
</joint>
<transmission name="Revolute_28_tran">
  <type>transmission_interface/SimpleTransmission</type>
  <joint name="Revolute_28">
    <hardwareInterface>PositionJointInterface</hardwareInterface>
  </joint>
  <actuator name="Revolute_28_actr">
    <hardwareInterface>PositionJointInterface</hardwareInterface>
    <mechanicalReduction>1</mechanicalReduction>
  </actuator>
</transmission>

<joint name="Revolute_32" type="continuous">
  <origin xyz="0.11 -4.2e-05 0.155049" rpy="0 0 0"/>
  <parent link="base11"/>
  <child link="base_top1"/>
  <axis xyz="1.0 0.0 0.0"/>
</joint>
<transmission name="Revolute_32_tran">
  <type>transmission_interface/SimpleTransmission</type>
  <joint name="Revolute_32">
    <hardwareInterface>PositionJointInterface</hardwareInterface>
  </joint>
  <actuator name="Revolute_32_actr">
    <hardwareInterface>PositionJointInterface</hardwareInterface>
    <mechanicalReduction>1</mechanicalReduction>
  </actuator>
</transmission>

<joint name="Revolute_33" type="continuous">
  <origin xyz="-0.054964 0.095284 0.150049" rpy="0 0 0"/>
  <parent link="base21"/>
  <child link="base_top21"/>
  <axis xyz="-0.5 0.866025 0.0"/>
</joint>
<transmission name="Revolute_33_tran">
  <type>transmission_interface/SimpleTransmission</type>
  <joint name="Revolute_33">
    <hardwareInterface>PositionJointInterface</hardwareInterface>
  </joint>
  <actuator name="Revolute_33_actr">
    <hardwareInterface>PositionJointInterface</hardwareInterface>
    <mechanicalReduction>1</mechanicalReduction>
  </actuator>
</transmission>

<joint name="Revolute_34" type="continuous">
  <origin xyz="-0.055036 -0.095242 0.145049" rpy="0 0 0"/>
  <parent link="base31"/>
  <child link="base_top31"/>
  <axis xyz="-0.5 -0.866025 0.0"/>
</joint>
<transmission name="Revolute_34_tran">
  <type>transmission_interface/SimpleTransmission</type>
  <joint name="Revolute_34">
    <hardwareInterface>PositionJointInterface</hardwareInterface>
  </joint>
  <actuator name="Revolute_34_actr">
    <hardwareInterface>PositionJointInterface</hardwareInterface>
    <mechanicalReduction>1</mechanicalReduction>
  </actuator>
</transmission>

</robot>
