<mujoco model="simple_example">

    <visual>
        <headlight ambient="0.5 0.5 0.5" />
    </visual>

    <asset>
        <material name="white" rgba="1 1 1 1" />
    </asset>

    <option gravity="0 0 -9.81" />

    <worldbody>
    <light diffuse=".5 .5 .5" pos="0 0 3" dir="0 0 -1"/>
        <geom type="plane" size="1 1 0.1" rgba="0 .9 0 1"/>
        <body pos="0 0 1" euler="0 0 0">
            <joint type="free"/>
            <inertial pos="0 0 0" mass="1" diaginertia="0.01 0.01 0.01"/>
            <geom type="box" size=".1 .2 .3" rgba=".9 0 0 1"/>
            <!-- COmment -->
            <!--geom type="box" size=".1 .2 .3" material="white"/-->
        </body>

        <body pos="0 0 1.5" euler="0 1.57 0">
            <joint type="free"/>
            <inertial pos="0 0 0" mass="1" diaginertia="0.01 0.01 0.01"/>
            <geom type="box" size=".1 .2 .3" rgba="0 0 .9 1"/>
        </body>

        <body pos="0.3 0 1.8" euler="0 1.57 0">
            <joint type="free"/>
            <inertial pos="0 0 0" mass="1" diaginertia="0.01 0.01 0.01"/>
            <geom type="sphere" size=".1" rgba=".5 .5 .5 1"/>
        </body>

        <light name="top" pos="0 0 3"/>
        <body name="box_and_sphere" euler="0 0 -30">
            <joint name="swing" type="hinge" axis="1 -1 0" pos="-.2 -.2 -.2"/>
            <geom name="red_box" type="box" size=".2 .2 .2" rgba="1 0 0 1"/>
            <geom name="green_sphere" pos=".2 .2 .2" size=".1" rgba="0 1 0 1"/>
        </body>
    </worldbody>

</mujoco>